Done.
Setting up the random seed for reproducibility...
Done.
dynamic_import - class_name:  OracleTrainer
Initializing model...
Done.
Initializing datasets...
Done.
Initializing clients...
dynamic_import - class_name:  OracleClient
filename: data/MIX_DATA/cityscapes/data/leftImg8bit/trainRGB/dusseldorf/dusseldorf_000164_000019_leftImg8bit.png
filename: data/MIX_DATA/cityscapes/data/leftImg8bit/trainRGB/dusseldorf/dusseldorf_000123_000019_leftImg8bit.png
filename: data/MIX_DATA/cityscapes/data/leftImg8bit/trainRGB/dusseldorf/dusseldorf_000134_000019_leftImg8bit.png
filename: data/MIX_DATA/cityscapes/data/leftImg8bit/trainRGB/dusseldorf/dusseldorf_000199_000019_leftImg8bit.png
filename: data/MIX_DATA/cityscapes/data/leftImg8bit/trainRGB/dusseldorf/dusseldorf_000035_000019_leftImg8bit.png
filename: data/MIX_DATA/cityscapes/data/leftImg8bit/trainRGB/dusseldorf/dusseldorf_000184_000019_leftImg8bit.png
filename: data/MIX_DATA/cityscapes/data/leftImg8bit/trainRGB/dusseldorf/dusseldorf_000191_000019_leftImg8bit.png
filename: data/MIX_DATA/cityscapes/data/leftImg8bit/trainRGB/dusseldorf/dusseldorf_000047_000019_leftImg8bit.png
filename: data/MIX_DATA/cityscapes/data/leftImg8bit/trainRGB/dusseldorf/dusseldorf_000208_000019_leftImg8bit.png
Traceback (most recent call last):
  File "/home/utente/anaconda3/envs/LADD/lib/python3.9/site-packages/torch/utils/data/dataloader.py", line 521, in __next__
    data = self._next_data()
  File "/home/utente/anaconda3/envs/LADD/lib/python3.9/site-packages/torch/utils/data/dataloader.py", line 1203, in _next_data
    return self._process_data(data)
  File "/home/utente/anaconda3/envs/LADD/lib/python3.9/site-packages/torch/utils/data/dataloader.py", line 1229, in _process_data
    data.reraise()
  File "/home/utente/anaconda3/envs/LADD/lib/python3.9/site-packages/torch/_utils.py", line 434, in reraise
    raise exception
TypeError: Caught TypeError in DataLoader worker process 0.
Original Traceback (most recent call last):
  File "/home/utente/anaconda3/envs/LADD/lib/python3.9/site-packages/torch/utils/data/_utils/worker.py", line 287, in _worker_loop
    data = fetcher.fetch(index)
  File "/home/utente/anaconda3/envs/LADD/lib/python3.9/site-packages/torch/utils/data/_utils/fetch.py", line 49, in fetch
    data = [self.dataset[idx] for idx in possibly_batched_index]
  File "/home/utente/anaconda3/envs/LADD/lib/python3.9/site-packages/torch/utils/data/_utils/fetch.py", line 49, in <listcomp>
    data = [self.dataset[idx] for idx in possibly_batched_index]
  File "/home/utente/Scrivania/PROVA/LADD/src/dataset/target/target_dataset.py", line 58, in __getitem__
    return self._apply_train_transform(x, y, x_hpf)
  File "/home/utente/Scrivania/PROVA/LADD/src/dataset/target/target_dataset.py", line 104, in _apply_train_transform
    x, y = self.transform(x, y)
  File "/home/utente/Scrivania/PROVA/LADD/src/dataset/transform.py", line 30, in __call__
    img, lbl = t(img, lbl)
  File "/home/utente/Scrivania/PROVA/LADD/src/dataset/transform.py", line 421, in __call__
    i, j, h, w = self.get_params(self, img, self.size)
TypeError: get_params() takes 3 positional arguments but 4 were given