Done.
Setting up the random seed for reproducibility...
Done.
dynamic_import - class_name:  OracleTrainer
Initializing model...
Done.
Initializing datasets...
Done.
Initializing clients...
dynamic_import - class_name:  OracleClient
Done.
Initializing server...
dynamic_import - class_name:  OracleServer
Running without server optimizer
Running without server optimizer
Done.
Initialize return score, metrics, ckpt, ckpt step...
Setting up metrics...
Done.
Setting up metrics...
Done.
Done.
Initializing optimizer and scheduler...
Done.
dynamic_import - class_name:  OracleClient
The experiment begins...
ROUND 1/1: Training 3 Clients...
CLIENT 1/3: erfurt5 RGB
Traceback (most recent call last):
  File "/home/utente/Scrivania/PROVA/LADD/src/run.py", line 53, in <module>
    run_experiment()
  File "/home/utente/Scrivania/PROVA/LADD/src/run.py", line 19, in run_experiment
    max_score,max_score_2 = trainer.train(*trainer.train_args, **trainer.train_kwargs)
  File "/home/utente/Scrivania/PROVA/LADD/src/federated/trainers/oracle_trainer.py", line 127, in train
    return self.perform_fed_oracle_training(
  File "/home/utente/Scrivania/PROVA/LADD/src/federated/trainers/oracle_trainer.py", line 42, in perform_fed_oracle_training
    losses, losses_2 = self.server.train_clients(partial_metric=partial_train_metric,  partial_metric_2=partial_train_metric_2)
  File "/home/utente/Scrivania/PROVA/LADD/src/federated/servers/oracle_server.py", line 70, in train_clients
    out = c.train(partial_metric_2, r=r)
  File "/home/utente/Scrivania/PROVA/LADD/src/clients/oracle_client.py", line 200, in train
    dict_all_iters_losses = self.run_epoch(epoch, optimizer, metric=partial_metric, r=r)
  File "/home/utente/Scrivania/PROVA/LADD/src/clients/oracle_client.py", line 170, in run_epoch
    self.__exec_epoch(optimizer, cur_epoch, metric, scheduler, plot_lr, dict_all_iters_losses,
  File "/home/utente/Scrivania/PROVA/LADD/src/clients/oracle_client.py", line 93, in __exec_epoch
    for cur_step, samples in enumerate(self.loader):
  File "/home/utente/anaconda3/envs/LADD/lib/python3.9/site-packages/torch/utils/data/dataloader.py", line 521, in __next__
    data = self._next_data()
  File "/home/utente/anaconda3/envs/LADD/lib/python3.9/site-packages/torch/utils/data/dataloader.py", line 1186, in _next_data
    idx, data = self._get_data()
  File "/home/utente/anaconda3/envs/LADD/lib/python3.9/site-packages/torch/utils/data/dataloader.py", line 1142, in _get_data
    success, data = self._try_get_data()
  File "/home/utente/anaconda3/envs/LADD/lib/python3.9/site-packages/torch/utils/data/dataloader.py", line 990, in _try_get_data
    data = self._data_queue.get(timeout=timeout)
  File "/home/utente/anaconda3/envs/LADD/lib/python3.9/queue.py", line 180, in get
    self.not_empty.wait(remaining)
  File "/home/utente/anaconda3/envs/LADD/lib/python3.9/threading.py", line 316, in wait
    gotit = waiter.acquire(True, timeout)
KeyboardInterrupt
During handling of the above exception, another exception occurred:
Traceback (most recent call last):
  File "/home/utente/pycharm/plugins/python-ce/helpers/pydev/pydevd.py", line 2195, in <module>
    main()
  File "/home/utente/pycharm/plugins/python-ce/helpers/pydev/pydevd.py", line 2179, in main
    handle_keyboard_interrupt()
  File "/home/utente/pycharm/plugins/python-ce/helpers/pydev/pydevd.py", line 1997, in handle_keyboard_interrupt
    traceback.print_exception(type(value), value, tb, limit=limit)
  File "/home/utente/anaconda3/envs/LADD/lib/python3.9/traceback.py", line 103, in print_exception
    for line in TracebackException(
  File "/home/utente/anaconda3/envs/LADD/lib/python3.9/traceback.py", line 517, in __init__
    self.stack = StackSummary.extract(
  File "/home/utente/anaconda3/envs/LADD/lib/python3.9/traceback.py", line 366, in extract
    f.line
  File "/home/utente/anaconda3/envs/LADD/lib/python3.9/traceback.py", line 288, in line
    self._line = linecache.getline(self.filename, self.lineno).strip()
  File "/home/utente/anaconda3/envs/LADD/lib/python3.9/linecache.py", line 30, in getline
    lines = getlines(filename, module_globals)
  File "/home/utente/anaconda3/envs/LADD/lib/python3.9/linecache.py", line 46, in getlines
    return updatecache(filename, module_globals)
  File "/home/utente/anaconda3/envs/LADD/lib/python3.9/linecache.py", line 137, in updatecache
    lines = fp.readlines()
  File "/home/utente/anaconda3/envs/LADD/lib/python3.9/codecs.py", line 319, in decode
    def decode(self, input, final=False):
KeyboardInterrupt