2023-06-27 11:25:19,548 INFO    MainThread:2816 [internal.py:wandb_internal():86] W&B internal server running at pid: 2816, started at: 2023-06-27 11:25:19.547702
2023-06-27 11:25:19,582 DEBUG   SenderThread:2816 [sender.py:send():182] send: header
2023-06-27 11:25:19,582 INFO    WriterThread:2816 [datastore.py:open_for_write():77] open: /home/utente/Scrivania/PROVA/LADD/wandb/run-20230627_112517-2d348cl9/run-2d348cl9.wandb
2023-06-27 11:25:19,590 DEBUG   HandlerThread:2816 [handler.py:handle_request():126] handle_request: check_version
2023-06-27 11:25:19,590 DEBUG   SenderThread:2816 [sender.py:send_request():196] send_request: check_version
2023-06-27 11:25:19,651 DEBUG   SenderThread:2816 [sender.py:send():182] send: run
2023-06-27 11:25:19,658 INFO    SenderThread:2816 [sender.py:_maybe_setup_resume():421] checking resume status for alessandro-fella-1/federated_cityscapes/2d348cl9
2023-06-27 11:25:23,073 ERROR   SenderThread:2816 [retry.py:__call__():126] Retry attempt failed:
Traceback (most recent call last):
  File "/home/utente/anaconda3/envs/LADD/lib/python3.9/site-packages/urllib3/connection.py", line 174, in _new_conn
    conn = connection.create_connection(
  File "/home/utente/anaconda3/envs/LADD/lib/python3.9/site-packages/urllib3/util/connection.py", line 73, in create_connection
    for res in socket.getaddrinfo(host, port, family, socket.SOCK_STREAM):
  File "/home/utente/anaconda3/envs/LADD/lib/python3.9/socket.py", line 954, in getaddrinfo
    for res in _socket.getaddrinfo(host, port, family, type, proto, flags):
socket.gaierror: [Errno -3] Temporary failure in name resolution

During handling of the above exception, another exception occurred:

Traceback (most recent call last):
  File "/home/utente/anaconda3/envs/LADD/lib/python3.9/site-packages/urllib3/connectionpool.py", line 699, in urlopen
    httplib_response = self._make_request(
  File "/home/utente/anaconda3/envs/LADD/lib/python3.9/site-packages/urllib3/connectionpool.py", line 382, in _make_request
    self._validate_conn(conn)
  File "/home/utente/anaconda3/envs/LADD/lib/python3.9/site-packages/urllib3/connectionpool.py", line 1010, in _validate_conn
    conn.connect()
  File "/home/utente/anaconda3/envs/LADD/lib/python3.9/site-packages/urllib3/connection.py", line 358, in connect
    conn = self._new_conn()
  File "/home/utente/anaconda3/envs/LADD/lib/python3.9/site-packages/urllib3/connection.py", line 186, in _new_conn
    raise NewConnectionError(
urllib3.exceptions.NewConnectionError: <urllib3.connection.HTTPSConnection object at 0x7f8208237220>: Failed to establish a new connection: [Errno -3] Temporary failure in name resolution

During handling of the above exception, another exception occurred:

Traceback (most recent call last):
  File "/home/utente/anaconda3/envs/LADD/lib/python3.9/site-packages/requests/adapters.py", line 440, in send
    resp = conn.urlopen(
  File "/home/utente/anaconda3/envs/LADD/lib/python3.9/site-packages/urllib3/connectionpool.py", line 755, in urlopen
    retries = retries.increment(
  File "/home/utente/anaconda3/envs/LADD/lib/python3.9/site-packages/urllib3/util/retry.py", line 574, in increment
    raise MaxRetryError(_pool, url, error or ResponseError(cause))
urllib3.exceptions.MaxRetryError: HTTPSConnectionPool(host='api.wandb.ai', port=443): Max retries exceeded with url: /graphql (Caused by NewConnectionError('<urllib3.connection.HTTPSConnection object at 0x7f8208237220>: Failed to establish a new connection: [Errno -3] Temporary failure in name resolution'))

During handling of the above exception, another exception occurred:

Traceback (most recent call last):
  File "/home/utente/anaconda3/envs/LADD/lib/python3.9/site-packages/wandb/sdk/lib/retry.py", line 102, in __call__
    result = self._call_fn(*args, **kwargs)
  File "/home/utente/anaconda3/envs/LADD/lib/python3.9/site-packages/wandb/sdk/internal/internal_api.py", line 130, in execute
    return self.client.execute(*args, **kwargs)
  File "/home/utente/anaconda3/envs/LADD/lib/python3.9/site-packages/wandb/vendor/gql-0.2.0/gql/client.py", line 52, in execute
    result = self._get_result(document, *args, **kwargs)
  File "/home/utente/anaconda3/envs/LADD/lib/python3.9/site-packages/wandb/vendor/gql-0.2.0/gql/client.py", line 60, in _get_result
    return self.transport.execute(document, *args, **kwargs)
  File "/home/utente/anaconda3/envs/LADD/lib/python3.9/site-packages/wandb/vendor/gql-0.2.0/gql/transport/requests.py", line 38, in execute
    request = requests.post(self.url, **post_args)
  File "/home/utente/anaconda3/envs/LADD/lib/python3.9/site-packages/requests/api.py", line 117, in post
    return request('post', url, data=data, json=json, **kwargs)
  File "/home/utente/anaconda3/envs/LADD/lib/python3.9/site-packages/requests/api.py", line 61, in request
    return session.request(method=method, url=url, **kwargs)
  File "/home/utente/anaconda3/envs/LADD/lib/python3.9/site-packages/requests/sessions.py", line 529, in request
    resp = self.send(prep, **send_kwargs)
  File "/home/utente/anaconda3/envs/LADD/lib/python3.9/site-packages/requests/sessions.py", line 645, in send
    r = adapter.send(request, **kwargs)
  File "/home/utente/anaconda3/envs/LADD/lib/python3.9/site-packages/requests/adapters.py", line 519, in send
    raise ConnectionError(e, request=request)
requests.exceptions.ConnectionError: HTTPSConnectionPool(host='api.wandb.ai', port=443): Max retries exceeded with url: /graphql (Caused by NewConnectionError('<urllib3.connection.HTTPSConnection object at 0x7f8208237220>: Failed to establish a new connection: [Errno -3] Temporary failure in name resolution'))
2023-06-27 11:25:28,677 DEBUG   HandlerThread:2816 [handler.py:handle_request():126] handle_request: run_start
2023-06-27 11:25:28,701 DEBUG   HandlerThread:2816 [meta.py:__init__():40] meta init
2023-06-27 11:25:28,701 DEBUG   HandlerThread:2816 [meta.py:__init__():54] meta init done
2023-06-27 11:25:28,702 DEBUG   HandlerThread:2816 [meta.py:probe():211] probe
2023-06-27 11:25:28,709 DEBUG   HandlerThread:2816 [meta.py:_setup_git():201] setup git
2023-06-27 11:25:28,773 INFO    SenderThread:2816 [dir_watcher.py:__init__():169] watching files in: /home/utente/Scrivania/PROVA/LADD/wandb/run-20230627_112517-2d348cl9/files
2023-06-27 11:25:28,774 INFO    SenderThread:2816 [sender.py:_start_run_threads():740] run started: 2d348cl9 with start time 1687857917
2023-06-27 11:25:28,774 DEBUG   SenderThread:2816 [sender.py:send():182] send: summary
2023-06-27 11:25:28,776 INFO    SenderThread:2816 [sender.py:_save_file():873] saving file wandb-summary.json with policy end
2023-06-27 11:25:28,779 DEBUG   HandlerThread:2816 [meta.py:_setup_git():208] setup git done
2023-06-27 11:25:28,779 DEBUG   HandlerThread:2816 [meta.py:_save_pip():58] save pip
2023-06-27 11:25:28,782 DEBUG   HandlerThread:2816 [meta.py:_save_pip():72] save pip done
2023-06-27 11:25:28,782 DEBUG   HandlerThread:2816 [meta.py:_save_conda():79] save conda
2023-06-27 11:25:29,759 INFO    Thread-14 :2816 [dir_watcher.py:_on_file_created():217] file/dir created: /home/utente/Scrivania/PROVA/LADD/wandb/run-20230627_112517-2d348cl9/files/conda-environment.yaml
2023-06-27 11:25:29,760 INFO    Thread-14 :2816 [dir_watcher.py:_on_file_created():217] file/dir created: /home/utente/Scrivania/PROVA/LADD/wandb/run-20230627_112517-2d348cl9/files/wandb-summary.json
2023-06-27 11:25:29,761 INFO    Thread-14 :2816 [dir_watcher.py:_on_file_created():217] file/dir created: /home/utente/Scrivania/PROVA/LADD/wandb/run-20230627_112517-2d348cl9/files/requirements.txt
2023-06-27 11:25:33,750 INFO    Thread-14 :2816 [dir_watcher.py:_on_file_created():217] file/dir created: /home/utente/Scrivania/PROVA/LADD/wandb/run-20230627_112517-2d348cl9/files/output.log
2023-06-27 11:25:34,065 DEBUG   HandlerThread:2816 [meta.py:_save_conda():87] save conda done
2023-06-27 11:25:34,065 DEBUG   HandlerThread:2816 [meta.py:probe():249] probe done
2023-06-27 11:25:34,330 DEBUG   HandlerThread:2816 [handler.py:handle_request():126] handle_request: stop_status
2023-06-27 11:25:34,330 DEBUG   SenderThread:2816 [sender.py:send_request():196] send_request: stop_status
2023-06-27 11:25:34,751 INFO    Thread-14 :2816 [dir_watcher.py:_on_file_modified():230] file/dir modified: /home/utente/Scrivania/PROVA/LADD/wandb/run-20230627_112517-2d348cl9/files/conda-environment.yaml
2023-06-27 11:25:34,751 INFO    Thread-14 :2816 [dir_watcher.py:_on_file_created():217] file/dir created: /home/utente/Scrivania/PROVA/LADD/wandb/run-20230627_112517-2d348cl9/files/wandb-metadata.json
2023-06-27 11:25:34,854 DEBUG   SenderThread:2816 [sender.py:send():182] send: metric
2023-06-27 11:25:34,854 DEBUG   SenderThread:2816 [sender.py:send():182] send: metric
2023-06-27 11:25:34,855 WARNING SenderThread:2816 [sender.py:send_metric():831] Seen metric with glob (shouldnt happen)
2023-06-27 11:25:34,855 DEBUG   SenderThread:2816 [sender.py:send():182] send: config
2023-06-27 11:25:34,857 DEBUG   SenderThread:2816 [sender.py:send():182] send: files
2023-06-27 11:25:34,857 INFO    SenderThread:2816 [sender.py:_save_file():873] saving file wandb-metadata.json with policy now
2023-06-27 11:25:35,988 INFO    Thread-16 :2816 [upload_job.py:push():137] Uploaded file /tmp/tmpp1cpo92uwandb/ff4xrrnw-wandb-metadata.json
2023-06-27 11:25:42,755 INFO    Thread-14 :2816 [dir_watcher.py:_on_file_modified():230] file/dir modified: /home/utente/Scrivania/PROVA/LADD/wandb/run-20230627_112517-2d348cl9/files/output.log
2023-06-27 11:25:44,757 INFO    Thread-14 :2816 [dir_watcher.py:_on_file_modified():230] file/dir modified: /home/utente/Scrivania/PROVA/LADD/wandb/run-20230627_112517-2d348cl9/files/output.log
2023-06-27 11:25:46,769 INFO    Thread-14 :2816 [dir_watcher.py:_on_file_modified():230] file/dir modified: /home/utente/Scrivania/PROVA/LADD/wandb/run-20230627_112517-2d348cl9/files/output.log
2023-06-27 11:25:50,334 DEBUG   HandlerThread:2816 [handler.py:handle_request():126] handle_request: stop_status
2023-06-27 11:25:55,588 DEBUG   SenderThread:2816 [sender.py:send_request():196] send_request: stop_status
2023-06-27 11:25:59,691 INFO    Thread-14 :2816 [dir_watcher.py:_on_file_modified():230] file/dir modified: /home/utente/Scrivania/PROVA/LADD/wandb/run-20230627_112517-2d348cl9/files/config.yaml
2023-06-27 11:26:04,425 DEBUG   SenderThread:2816 [sender.py:send():182] send: stats
2023-06-27 11:26:10,691 WARNING MainThread:2816 [internal.py:is_dead():364] Internal process exiting, parent pid 2699 disappeared
2023-06-27 11:26:10,692 ERROR   MainThread:2816 [internal.py:wandb_internal():141] Internal process shutdown.
2023-06-27 11:26:11,429 INFO    WriterThread:2816 [datastore.py:close():281] close: /home/utente/Scrivania/PROVA/LADD/wandb/run-20230627_112517-2d348cl9/run-2d348cl9.wandb
2023-06-27 11:26:11,431 INFO    SenderThread:2816 [sender.py:finish():979] shutting down sender
2023-06-27 11:26:11,432 INFO    SenderThread:2816 [dir_watcher.py:finish():283] shutting down directory watcher
2023-06-27 11:26:11,438 INFO    HandlerThread:2816 [handler.py:finish():683] shutting down handler
2023-06-27 11:26:11,701 INFO    SenderThread:2816 [dir_watcher.py:finish():313] scan: /home/utente/Scrivania/PROVA/LADD/wandb/run-20230627_112517-2d348cl9/files
2023-06-27 11:26:11,702 INFO    SenderThread:2816 [dir_watcher.py:finish():327] scan save: /home/utente/Scrivania/PROVA/LADD/wandb/run-20230627_112517-2d348cl9/files/config.yaml config.yaml
2023-06-27 11:26:11,704 INFO    SenderThread:2816 [dir_watcher.py:finish():327] scan save: /home/utente/Scrivania/PROVA/LADD/wandb/run-20230627_112517-2d348cl9/files/requirements.txt requirements.txt
2023-06-27 11:26:11,711 INFO    SenderThread:2816 [dir_watcher.py:finish():327] scan save: /home/utente/Scrivania/PROVA/LADD/wandb/run-20230627_112517-2d348cl9/files/output.log output.log
2023-06-27 11:26:11,712 INFO    SenderThread:2816 [dir_watcher.py:finish():327] scan save: /home/utente/Scrivania/PROVA/LADD/wandb/run-20230627_112517-2d348cl9/files/wandb-summary.json wandb-summary.json
2023-06-27 11:26:11,712 INFO    SenderThread:2816 [dir_watcher.py:finish():327] scan save: /home/utente/Scrivania/PROVA/LADD/wandb/run-20230627_112517-2d348cl9/files/conda-environment.yaml conda-environment.yaml
2023-06-27 11:26:11,713 INFO    SenderThread:2816 [dir_watcher.py:finish():327] scan save: /home/utente/Scrivania/PROVA/LADD/wandb/run-20230627_112517-2d348cl9/files/wandb-metadata.json wandb-metadata.json
2023-06-27 11:26:11,713 INFO    SenderThread:2816 [file_pusher.py:finish():177] shutting down file pusher
2023-06-27 11:26:11,713 INFO    SenderThread:2816 [file_pusher.py:join():182] waiting for file pusher
2023-06-27 11:26:12,606 INFO    Thread-17 :2816 [upload_job.py:push():137] Uploaded file /home/utente/Scrivania/PROVA/LADD/wandb/run-20230627_112517-2d348cl9/files/config.yaml
2023-06-27 11:26:12,609 INFO    Thread-20 :2816 [upload_job.py:push():137] Uploaded file /home/utente/Scrivania/PROVA/LADD/wandb/run-20230627_112517-2d348cl9/files/wandb-summary.json
2023-06-27 11:26:12,613 INFO    Thread-19 :2816 [upload_job.py:push():137] Uploaded file /home/utente/Scrivania/PROVA/LADD/wandb/run-20230627_112517-2d348cl9/files/output.log
2023-06-27 11:26:12,618 INFO    Thread-21 :2816 [upload_job.py:push():137] Uploaded file /home/utente/Scrivania/PROVA/LADD/wandb/run-20230627_112517-2d348cl9/files/conda-environment.yaml
2023-06-27 11:26:12,620 INFO    Thread-18 :2816 [upload_job.py:push():137] Uploaded file /home/utente/Scrivania/PROVA/LADD/wandb/run-20230627_112517-2d348cl9/files/requirements.txt
2023-06-27 11:26:13,803 INFO    MainThread:2816 [internal.py:handle_exit():76] Internal process exited
