Done.
Setting up the random seed for reproducibility...
Done.
Initializing model...
Done.
Initializing datasets...
Done.
Initializing clients...
Error evaluating: thread_id: pid_11740_id_139756836862224
frame_id: 139751577068016
scope: FRAME
attrs: self
Traceback (most recent call last):
  File "/home/utente/pycharm/plugins/python-ce/helpers/pydev/_pydevd_bundle/pydevd_vars.py", line 315, in resolve_compound_variable_fields
    return _typeName, _resolve_default_variable_fields(var, resolver, offset)
  File "/home/utente/pycharm/plugins/python-ce/helpers/pydev/_pydevd_bundle/pydevd_vars.py", line 265, in _resolve_default_variable_fields
    return resolver.get_dictionary(VariableWithOffset(var, offset) if offset else var)
  File "/home/utente/pycharm/plugins/python-ce/helpers/pydev/_pydevd_bundle/pydevd_resolver.py", line 86, in get_dictionary
    return self._getPyDictionary(var, names)
  File "/home/utente/pycharm/plugins/python-ce/helpers/pydev/_pydevd_bundle/pydevd_resolver.py", line 159, in _getPyDictionary
    names = self.get_names(var)
  File "/home/utente/pycharm/plugins/python-ce/helpers/pydev/_pydevd_bundle/pydevd_resolver.py", line 147, in get_names
    names = dir(var)
  File "/home/utente/anaconda3/envs/LADD/lib/python3.9/site-packages/torch/nn/modules/module.py", line 1832, in __dir__
    parameters = list(self._parameters.keys())
  File "/home/utente/anaconda3/envs/LADD/lib/python3.9/site-packages/torch/nn/modules/module.py", line 1177, in __getattr__
    raise AttributeError("'{}' object has no attribute '{}'".format(
AttributeError: 'HardNegativeMining' object has no attribute '_parameters'
Traceback (most recent call last):
  File "/home/utente/Scrivania/PROVA/LADD/src/run.py", line 47, in <module>
    run_experiment()
  File "/home/utente/Scrivania/PROVA/LADD/src/run.py", line 15, in run_experiment
    trainer = trainer_class(args, writer, device, rank, world_size)
  File "/home/utente/Scrivania/PROVA/LADD/src/federated/trainers/oracle_trainer.py", line 9, in __init__
    super().__init__(args, writer, device, rank, world_size)
  File "/home/utente/Scrivania/PROVA/LADD/src/federated/trainers/trainer.py", line 11, in __init__
    super().__init__(args, writer, device, rank, world_size)
  File "/home/utente/Scrivania/PROVA/LADD/src/general_trainer.py", line 50, in __init__
    self.__clients_setup()
Traceback (most recent call last):
  File "/home/utente/Scrivania/PROVA/LADD/src/run.py", line 47, in <module>
    run_experiment()
  File "/home/utente/Scrivania/PROVA/LADD/src/run.py", line 15, in run_experiment
    trainer = trainer_class(args, writer, device, rank, world_size)
  File "/home/utente/Scrivania/PROVA/LADD/src/federated/trainers/oracle_trainer.py", line 9, in __init__
    super().__init__(args, writer, device, rank, world_size)
  File "/home/utente/Scrivania/PROVA/LADD/src/federated/trainers/trainer.py", line 11, in __init__
    super().__init__(args, writer, device, rank, world_size)
  File "/home/utente/Scrivania/PROVA/LADD/src/general_trainer.py", line 50, in __init__
    self.__clients_setup()
  File "/home/utente/Scrivania/PROVA/LADD/src/general_trainer.py", line 126, in __clients_setup
    cl = client_class(**cl_args, batch_size=batch_size, test_user=split == 'test')
  File "/home/utente/Scrivania/PROVA/LADD/src/clients/oracle_client.py", line 18, in __init__
    self.teacher_kd_model = None
  File "/home/utente/Scrivania/PROVA/LADD/src/clients/oracle_client.py", line 18, in __init__
    self.teacher_kd_model = None
  File "_pydevd_bundle/pydevd_cython.pyx", line 1179, in _pydevd_bundle.pydevd_cython.SafeCallWrapper.__call__
  File "_pydevd_bundle/pydevd_cython.pyx", line 620, in _pydevd_bundle.pydevd_cython.PyDBFrame.trace_dispatch
  File "_pydevd_bundle/pydevd_cython.pyx", line 1095, in _pydevd_bundle.pydevd_cython.PyDBFrame.trace_dispatch
  File "_pydevd_bundle/pydevd_cython.pyx", line 1057, in _pydevd_bundle.pydevd_cython.PyDBFrame.trace_dispatch
  File "_pydevd_bundle/pydevd_cython.pyx", line 317, in _pydevd_bundle.pydevd_cython.PyDBFrame.do_wait_suspend
  File "/home/utente/pycharm/plugins/python-ce/helpers/pydev/pydevd.py", line 1160, in do_wait_suspend
    self._do_wait_suspend(thread, frame, event, arg, suspend_type, from_this_thread)
  File "/home/utente/pycharm/plugins/python-ce/helpers/pydev/pydevd.py", line 1175, in _do_wait_suspend
    time.sleep(0.01)
KeyboardInterrupt
During handling of the above exception, another exception occurred:
Traceback (most recent call last):
  File "/home/utente/pycharm/plugins/python-ce/helpers/pydev/pydevd.py", line 2195, in <module>
    main()
  File "/home/utente/pycharm/plugins/python-ce/helpers/pydev/pydevd.py", line 2179, in main
    handle_keyboard_interrupt()
  File "/home/utente/pycharm/plugins/python-ce/helpers/pydev/pydevd.py", line 1997, in handle_keyboard_interrupt
    traceback.print_exception(type(value), value, tb, limit=limit)
  File "/home/utente/anaconda3/envs/LADD/lib/python3.9/traceback.py", line 105, in print_exception
    print(line, file=file, end="")
KeyboardInterrupt