Done.
Setting up the random seed for reproducibility...
Done.
dynamic_import - class_name:  OracleTrainer
Initializing model...
Done.
Initializing datasets...
Done.
Initializing clients...
dynamic_import - class_name:  OracleClient
Done.
Initializing server...
dynamic_import - class_name:  OracleServer
Running without server optimizer
Done.
Initialize return score, metrics, ckpt, ckpt step...
Setting up metrics...
Done.
Done.
Initializing optimizer and scheduler...
Done.
dynamic_import - class_name:  OracleClient
The experiment begins...
ROUND 1/1: Training 5 Clients...
CLIENT 1/5: erfurt5 MIX
EPOCH 1: ended.
Traceback (most recent call last):
  File "/home/utente/Scrivania/PROVA/LADD/src/run.py", line 53, in <module>
    run_experiment()
  File "/home/utente/Scrivania/PROVA/LADD/src/run.py", line 21, in run_experiment
    max_score = trainer.train(*trainer.train_args, **trainer.train_kwargs)
  File "/home/utente/Scrivania/PROVA/LADD/src/federated/trainers/oracle_trainer.py", line 136, in train
    return self.perform_fed_oracle_training(
Traceback (most recent call last):
  File "/home/utente/Scrivania/PROVA/LADD/src/run.py", line 53, in <module>
    run_experiment()
  File "/home/utente/Scrivania/PROVA/LADD/src/run.py", line 21, in run_experiment
    max_score = trainer.train(*trainer.train_args, **trainer.train_kwargs)
  File "/home/utente/Scrivania/PROVA/LADD/src/federated/trainers/oracle_trainer.py", line 136, in train
    return self.perform_fed_oracle_training(
  File "/home/utente/Scrivania/PROVA/LADD/src/federated/trainers/oracle_trainer.py", line 99, in perform_fed_oracle_training
    losses = self.server.train_clients(partial_metric=partial_train_metric)
  File "/home/utente/Scrivania/PROVA/LADD/src/federated/servers/oracle_server.py", line 113, in train_clients
    out = c.train(partial_metric, r=r)
  File "/home/utente/Scrivania/PROVA/LADD/src/clients/oracle_client.py", line 209, in train
    if self.args.local_rank == 0:
  File "/home/utente/Scrivania/PROVA/LADD/src/clients/oracle_client.py", line 209, in train
    if self.args.local_rank == 0:
  File "_pydevd_bundle/pydevd_cython.pyx", line 1179, in _pydevd_bundle.pydevd_cython.SafeCallWrapper.__call__
  File "_pydevd_bundle/pydevd_cython.pyx", line 620, in _pydevd_bundle.pydevd_cython.PyDBFrame.trace_dispatch
  File "_pydevd_bundle/pydevd_cython.pyx", line 929, in _pydevd_bundle.pydevd_cython.PyDBFrame.trace_dispatch
  File "_pydevd_bundle/pydevd_cython.pyx", line 920, in _pydevd_bundle.pydevd_cython.PyDBFrame.trace_dispatch
  File "_pydevd_bundle/pydevd_cython.pyx", line 317, in _pydevd_bundle.pydevd_cython.PyDBFrame.do_wait_suspend
  File "/home/utente/pycharm/plugins/python-ce/helpers/pydev/pydevd.py", line 1160, in do_wait_suspend
    self._do_wait_suspend(thread, frame, event, arg, suspend_type, from_this_thread)
  File "/home/utente/pycharm/plugins/python-ce/helpers/pydev/pydevd.py", line 1175, in _do_wait_suspend
    time.sleep(0.01)
KeyboardInterrupt
During handling of the above exception, another exception occurred:
Traceback (most recent call last):
  File "/home/utente/pycharm/plugins/python-ce/helpers/pydev/pydevd.py", line 2195, in <module>
    main()
  File "/home/utente/pycharm/plugins/python-ce/helpers/pydev/pydevd.py", line 2179, in main
    handle_keyboard_interrupt()
  File "/home/utente/pycharm/plugins/python-ce/helpers/pydev/pydevd.py", line 1997, in handle_keyboard_interrupt
    traceback.print_exception(type(value), value, tb, limit=limit)
  File "/home/utente/anaconda3/envs/LADD/lib/python3.9/traceback.py", line 105, in print_exception
    print(line, file=file, end="")
KeyboardInterrupt