Done.
Setting up the random seed for reproducibility...
Done.
dynamic_import - class_name:  OracleTrainer
Initializing model...
Done.
Initializing datasets...
Done.
Initializing clients...
dynamic_import - class_name:  OracleClient
Done.
Initializing server...
dynamic_import - class_name:  OracleServer
Running without server optimizer
Running without server optimizer
Done.
Initialize return score, metrics, ckpt, ckpt step...
Setting up metrics...
Done.
Setting up metrics...
Done.
Done.
Initializing optimizer and scheduler...
Done.
dynamic_import - class_name:  OracleClient
The experiment begins...
ROUND 1/15: Training 2 Clients...
Traceback (most recent call last):
  File "/home/utente/Scrivania/PROVA/LADD/src/run.py", line 51, in <module>
    run_experiment()
Traceback (most recent call last):
  File "/home/utente/Scrivania/PROVA/LADD/src/run.py", line 51, in <module>
    run_experiment()
  File "/home/utente/Scrivania/PROVA/LADD/src/run.py", line 20, in run_experiment
    max_score,max_score_2 = trainer.train(*trainer.train_args, **trainer.train_kwargs)
  File "/home/utente/Scrivania/PROVA/LADD/src/federated/trainers/oracle_trainer.py", line 99, in train
    return self.perform_fed_oracle_training(
  File "/home/utente/Scrivania/PROVA/LADD/src/federated/trainers/oracle_trainer.py", line 38, in perform_fed_oracle_training
    self.server.select_clients(r, self.target_train_clients, num_clients=self.args.clients_per_round)
  File "/home/utente/Scrivania/PROVA/LADD/src/federated/trainers/oracle_trainer.py", line 38, in perform_fed_oracle_training
    self.server.select_clients(r, self.target_train_clients, num_clients=self.args.clients_per_round)
  File "_pydevd_bundle/pydevd_cython.pyx", line 1179, in _pydevd_bundle.pydevd_cython.SafeCallWrapper.__call__
  File "_pydevd_bundle/pydevd_cython.pyx", line 620, in _pydevd_bundle.pydevd_cython.PyDBFrame.trace_dispatch
  File "_pydevd_bundle/pydevd_cython.pyx", line 929, in _pydevd_bundle.pydevd_cython.PyDBFrame.trace_dispatch
  File "_pydevd_bundle/pydevd_cython.pyx", line 920, in _pydevd_bundle.pydevd_cython.PyDBFrame.trace_dispatch
  File "_pydevd_bundle/pydevd_cython.pyx", line 317, in _pydevd_bundle.pydevd_cython.PyDBFrame.do_wait_suspend
  File "/home/utente/pycharm/plugins/python-ce/helpers/pydev/pydevd.py", line 1160, in do_wait_suspend
    self._do_wait_suspend(thread, frame, event, arg, suspend_type, from_this_thread)
  File "/home/utente/pycharm/plugins/python-ce/helpers/pydev/pydevd.py", line 1175, in _do_wait_suspend
    time.sleep(0.01)
KeyboardInterrupt
During handling of the above exception, another exception occurred:
Traceback (most recent call last):
  File "/home/utente/pycharm/plugins/python-ce/helpers/pydev/pydevd.py", line 2195, in <module>
    main()
  File "/home/utente/pycharm/plugins/python-ce/helpers/pydev/pydevd.py", line 2179, in main
    handle_keyboard_interrupt()
  File "/home/utente/pycharm/plugins/python-ce/helpers/pydev/pydevd.py", line 1997, in handle_keyboard_interrupt
    traceback.print_exception(type(value), value, tb, limit=limit)
  File "/home/utente/anaconda3/envs/LADD/lib/python3.9/traceback.py", line 105, in print_exception
    print(line, file=file, end="")
KeyboardInterrupt