Done.
Setting up the random seed for reproducibility...
Done.
class_name:  OracleTrainer
Initializing model...
Done.
Initializing datasets...
Done.
Initializing clients...
class_name:  OracleClient
Done.
Initializing server...
class_name:  OracleServer
Running without server optimizer
Done.
Initialize return score, metrics, ckpt, ckpt step...
Setting up metrics...
Done.
Done.
Initializing optimizer and scheduler...
Done.
Generating sample ids for plots...
Done.
class_name:  OracleClient
The experiment begins...
Lunghezza max_scores 1
ROUND 1/2: Training 2 Clients...
CLIENT 1/2: erfurt5 RGB
EPOCH 1: ended.
CLIENT 2/2: weimar3 RGB
EPOCH 1: ended.
[34m[1mwandb[39m[22m: Network error resolved after 0:27:29.290577, resuming normal operation.
Traceback (most recent call last):
  File "/home/utente/Scrivania/PROVA/LADD/src/run.py", line 47, in <module>
Traceback (most recent call last):
  File "/home/utente/Scrivania/PROVA/LADD/src/run.py", line 47, in <module>
  File "/home/utente/Scrivania/PROVA/LADD/src/run.py", line 18, in run_experiment
    writer.write("The experiment begins...")
  File "/home/utente/Scrivania/PROVA/LADD/src/federated/trainers/oracle_trainer.py", line 59, in train
    return max_scores
  File "/home/utente/Scrivania/PROVA/LADD/src/federated/trainers/oracle_trainer.py", line 37, in perform_fed_oracle_training
    #Class Oracle Server
  File "/home/utente/Scrivania/PROVA/LADD/src/federated/servers/oracle_server.py", line 47, in train_clients
  File "/home/utente/Scrivania/PROVA/LADD/src/federated/servers/oracle_server.py", line 47, in train_clients
  File "_pydevd_bundle/pydevd_cython.pyx", line 1589, in _pydevd_bundle.pydevd_cython.ThreadTracer.__call__
  File "_pydevd_bundle/pydevd_cython.pyx", line 929, in _pydevd_bundle.pydevd_cython.PyDBFrame.trace_dispatch
  File "_pydevd_bundle/pydevd_cython.pyx", line 920, in _pydevd_bundle.pydevd_cython.PyDBFrame.trace_dispatch
  File "_pydevd_bundle/pydevd_cython.pyx", line 317, in _pydevd_bundle.pydevd_cython.PyDBFrame.do_wait_suspend
  File "/home/utente/pycharm/plugins/python-ce/helpers/pydev/pydevd.py", line 1160, in do_wait_suspend
    self._do_wait_suspend(thread, frame, event, arg, suspend_type, from_this_thread)
  File "/home/utente/pycharm/plugins/python-ce/helpers/pydev/pydevd.py", line 1175, in _do_wait_suspend
    time.sleep(0.01)
KeyboardInterrupt
During handling of the above exception, another exception occurred:
Traceback (most recent call last):
  File "/home/utente/pycharm/plugins/python-ce/helpers/pydev/pydevd.py", line 2195, in <module>
    main()
  File "/home/utente/pycharm/plugins/python-ce/helpers/pydev/pydevd.py", line 2179, in main
    handle_keyboard_interrupt()
  File "/home/utente/pycharm/plugins/python-ce/helpers/pydev/pydevd.py", line 1997, in handle_keyboard_interrupt
    traceback.print_exception(type(value), value, tb, limit=limit)
  File "/home/utente/anaconda3/envs/LADD/lib/python3.9/traceback.py", line 105, in print_exception
    print(line, file=file, end="")
KeyboardInterrupt