Done.
Setting up the random seed for reproducibility...
Done.
dynamic_import - class_name:  OracleTrainer
Initializing model...
Done.
Initializing datasets...
Done.
Initializing clients...
dynamic_import - class_name:  OracleClient
Done.
Initializing server...
dynamic_import - class_name:  OracleServer
Running without server optimizer
Done.
Initialize return score, metrics, ckpt, ckpt step...
Setting up metrics...
Done.
Done.
Initializing optimizer and scheduler...
Done.
dynamic_import - class_name:  OracleClient
The experiment begins...
ROUND 1/6: Training 2 Clients...
CLIENT 1/2: erfurt5 MIX
Traceback (most recent call last):
  File "/home/utente/anaconda3/envs/LADD/lib/python3.9/site-packages/torch/utils/data/dataloader.py", line 990, in _try_get_data
    data = self._data_queue.get(timeout=timeout)
  File "/home/utente/anaconda3/envs/LADD/lib/python3.9/queue.py", line 180, in get
    self.not_empty.wait(remaining)
  File "/home/utente/anaconda3/envs/LADD/lib/python3.9/threading.py", line 316, in wait
    gotit = waiter.acquire(True, timeout)
  File "/home/utente/anaconda3/envs/LADD/lib/python3.9/site-packages/torch/utils/data/_utils/signal_handling.py", line 66, in handler
    _error_if_any_worker_fails()
RuntimeError: DataLoader worker (pid 3799) is killed by signal: Killed.
The above exception was the direct cause of the following exception:
Traceback (most recent call last):
  File "/home/utente/anaconda3/envs/LADD/lib/python3.9/site-packages/torch/utils/data/dataloader.py", line 521, in __next__
    data = self._next_data()
  File "/home/utente/anaconda3/envs/LADD/lib/python3.9/site-packages/torch/utils/data/dataloader.py", line 1186, in _next_data
    idx, data = self._get_data()
  File "/home/utente/anaconda3/envs/LADD/lib/python3.9/site-packages/torch/utils/data/dataloader.py", line 1142, in _get_data
    success, data = self._try_get_data()
  File "/home/utente/anaconda3/envs/LADD/lib/python3.9/site-packages/torch/utils/data/dataloader.py", line 1003, in _try_get_data
    raise RuntimeError('DataLoader worker (pid(s) {}) exited unexpectedly'.format(pids_str)) from e
RuntimeError: DataLoader worker (pid(s) 3799) exited unexpectedly
Traceback (most recent call last):
  File "/home/utente/anaconda3/envs/LADD/lib/python3.9/threading.py", line 910, in run
    self._target(*self._args, **self._kwargs)
  File "/home/utente/anaconda3/envs/LADD/lib/python3.9/site-packages/torch/utils/data/_utils/pin_memory.py", line 28, in _pin_memory_loop
    r = in_queue.get(timeout=MP_STATUS_CHECK_INTERVAL)
  File "/home/utente/anaconda3/envs/LADD/lib/python3.9/multiprocessing/queues.py", line 122, in get
    return _ForkingPickler.loads(res)
  File "/home/utente/anaconda3/envs/LADD/lib/python3.9/site-packages/torch/multiprocessing/reductions.py", line 289, in rebuild_storage_fd
    fd = df.detach()
  File "/home/utente/anaconda3/envs/LADD/lib/python3.9/multiprocessing/resource_sharer.py", line 57, in detach
    with _resource_sharer.get_connection(self._id) as conn:
  File "/home/utente/anaconda3/envs/LADD/lib/python3.9/multiprocessing/resource_sharer.py", line 86, in get_connection
    c = Client(address, authkey=process.current_process().authkey)
  File "/home/utente/anaconda3/envs/LADD/lib/python3.9/multiprocessing/connection.py", line 507, in Client
    c = SocketClient(address)
  File "/home/utente/anaconda3/envs/LADD/lib/python3.9/multiprocessing/connection.py", line 635, in SocketClient
    s.connect(address)
ConnectionRefusedError: [Errno 111] Connection refused
Exception in thread Thread-15:
Traceback (most recent call last):
  File "/home/utente/anaconda3/envs/LADD/lib/python3.9/threading.py", line 973, in _bootstrap_inner
    self.run()
  File "/home/utente/anaconda3/envs/LADD/lib/python3.9/threading.py", line 910, in run
    self._target(*self._args, **self._kwargs)
  File "/home/utente/anaconda3/envs/LADD/lib/python3.9/site-packages/torch/utils/data/_utils/pin_memory.py", line 28, in _pin_memory_loop
    r = in_queue.get(timeout=MP_STATUS_CHECK_INTERVAL)
  File "/home/utente/anaconda3/envs/LADD/lib/python3.9/multiprocessing/queues.py", line 122, in get
    return _ForkingPickler.loads(res)
  File "/home/utente/anaconda3/envs/LADD/lib/python3.9/site-packages/torch/multiprocessing/reductions.py", line 289, in rebuild_storage_fd
    fd = df.detach()
  File "/home/utente/anaconda3/envs/LADD/lib/python3.9/multiprocessing/resource_sharer.py", line 57, in detach
    with _resource_sharer.get_connection(self._id) as conn:
  File "/home/utente/anaconda3/envs/LADD/lib/python3.9/multiprocessing/resource_sharer.py", line 86, in get_connection
    c = Client(address, authkey=process.current_process().authkey)
  File "/home/utente/anaconda3/envs/LADD/lib/python3.9/multiprocessing/connection.py", line 507, in Client
    c = SocketClient(address)
  File "/home/utente/anaconda3/envs/LADD/lib/python3.9/multiprocessing/connection.py", line 635, in SocketClient
    s.connect(address)
ConnectionRefusedError: [Errno 111] Connection refused