2023-03-20 16:11:20,055 INFO    MainThread:5613 [internal.py:wandb_internal():86] W&B internal server running at pid: 5613, started at: 2023-03-20 16:11:20.055583
2023-03-20 16:11:20,058 DEBUG   HandlerThread:5613 [handler.py:handle_request():126] handle_request: check_version
2023-03-20 16:11:20,058 INFO    WriterThread:5613 [datastore.py:open_for_write():77] open: /home/utente/Scrivania/PROVA/LADD/wandb/run-20230320_161119-qq2aefz1/run-qq2aefz1.wandb
2023-03-20 16:11:20,059 DEBUG   SenderThread:5613 [sender.py:send():182] send: header
2023-03-20 16:11:20,059 DEBUG   SenderThread:5613 [sender.py:send_request():196] send_request: check_version
2023-03-20 16:11:20,064 DEBUG   SenderThread:5613 [sender.py:send():182] send: run
2023-03-20 16:11:20,065 INFO    SenderThread:5613 [sender.py:_maybe_setup_resume():421] checking resume status for alessandro-fella-1/federated_cityscapes/qq2aefz1
2023-03-20 16:11:23,274 WARNING MainThread:5613 [internal.py:wandb_internal():145] Internal process interrupt: 1
2023-03-20 16:11:23,513 ERROR   SenderThread:5613 [retry.py:__call__():126] Retry attempt failed:
Traceback (most recent call last):
  File "/home/utente/anaconda3/envs/LADD/lib/python3.9/site-packages/urllib3/connection.py", line 174, in _new_conn
    conn = connection.create_connection(
  File "/home/utente/anaconda3/envs/LADD/lib/python3.9/site-packages/urllib3/util/connection.py", line 73, in create_connection
    for res in socket.getaddrinfo(host, port, family, socket.SOCK_STREAM):
  File "/home/utente/anaconda3/envs/LADD/lib/python3.9/socket.py", line 954, in getaddrinfo
    for res in _socket.getaddrinfo(host, port, family, type, proto, flags):
socket.gaierror: [Errno -3] Temporary failure in name resolution

During handling of the above exception, another exception occurred:

Traceback (most recent call last):
  File "/home/utente/anaconda3/envs/LADD/lib/python3.9/site-packages/urllib3/connectionpool.py", line 699, in urlopen
    httplib_response = self._make_request(
  File "/home/utente/anaconda3/envs/LADD/lib/python3.9/site-packages/urllib3/connectionpool.py", line 382, in _make_request
    self._validate_conn(conn)
  File "/home/utente/anaconda3/envs/LADD/lib/python3.9/site-packages/urllib3/connectionpool.py", line 1010, in _validate_conn
    conn.connect()
  File "/home/utente/anaconda3/envs/LADD/lib/python3.9/site-packages/urllib3/connection.py", line 358, in connect
    conn = self._new_conn()
  File "/home/utente/anaconda3/envs/LADD/lib/python3.9/site-packages/urllib3/connection.py", line 186, in _new_conn
    raise NewConnectionError(
urllib3.exceptions.NewConnectionError: <urllib3.connection.HTTPSConnection object at 0x7ff7c92c48b0>: Failed to establish a new connection: [Errno -3] Temporary failure in name resolution

During handling of the above exception, another exception occurred:

Traceback (most recent call last):
  File "/home/utente/anaconda3/envs/LADD/lib/python3.9/site-packages/requests/adapters.py", line 440, in send
    resp = conn.urlopen(
  File "/home/utente/anaconda3/envs/LADD/lib/python3.9/site-packages/urllib3/connectionpool.py", line 755, in urlopen
    retries = retries.increment(
  File "/home/utente/anaconda3/envs/LADD/lib/python3.9/site-packages/urllib3/util/retry.py", line 574, in increment
    raise MaxRetryError(_pool, url, error or ResponseError(cause))
urllib3.exceptions.MaxRetryError: HTTPSConnectionPool(host='api.wandb.ai', port=443): Max retries exceeded with url: /graphql (Caused by NewConnectionError('<urllib3.connection.HTTPSConnection object at 0x7ff7c92c48b0>: Failed to establish a new connection: [Errno -3] Temporary failure in name resolution'))

During handling of the above exception, another exception occurred:

Traceback (most recent call last):
  File "/home/utente/anaconda3/envs/LADD/lib/python3.9/site-packages/wandb/sdk/lib/retry.py", line 102, in __call__
    result = self._call_fn(*args, **kwargs)
  File "/home/utente/anaconda3/envs/LADD/lib/python3.9/site-packages/wandb/sdk/internal/internal_api.py", line 130, in execute
    return self.client.execute(*args, **kwargs)
  File "/home/utente/anaconda3/envs/LADD/lib/python3.9/site-packages/wandb/vendor/gql-0.2.0/gql/client.py", line 52, in execute
    result = self._get_result(document, *args, **kwargs)
  File "/home/utente/anaconda3/envs/LADD/lib/python3.9/site-packages/wandb/vendor/gql-0.2.0/gql/client.py", line 60, in _get_result
    return self.transport.execute(document, *args, **kwargs)
  File "/home/utente/anaconda3/envs/LADD/lib/python3.9/site-packages/wandb/vendor/gql-0.2.0/gql/transport/requests.py", line 38, in execute
    request = requests.post(self.url, **post_args)
  File "/home/utente/anaconda3/envs/LADD/lib/python3.9/site-packages/requests/api.py", line 117, in post
    return request('post', url, data=data, json=json, **kwargs)
  File "/home/utente/anaconda3/envs/LADD/lib/python3.9/site-packages/requests/api.py", line 61, in request
    return session.request(method=method, url=url, **kwargs)
  File "/home/utente/anaconda3/envs/LADD/lib/python3.9/site-packages/requests/sessions.py", line 529, in request
    resp = self.send(prep, **send_kwargs)
  File "/home/utente/anaconda3/envs/LADD/lib/python3.9/site-packages/requests/sessions.py", line 645, in send
    r = adapter.send(request, **kwargs)
  File "/home/utente/anaconda3/envs/LADD/lib/python3.9/site-packages/requests/adapters.py", line 519, in send
    raise ConnectionError(e, request=request)
requests.exceptions.ConnectionError: HTTPSConnectionPool(host='api.wandb.ai', port=443): Max retries exceeded with url: /graphql (Caused by NewConnectionError('<urllib3.connection.HTTPSConnection object at 0x7ff7c92c48b0>: Failed to establish a new connection: [Errno -3] Temporary failure in name resolution'))
2023-03-20 16:11:46,360 WARNING MainThread:5613 [internal.py:wandb_internal():145] Internal process interrupt: 2
2023-03-20 16:11:46,360 ERROR   MainThread:5613 [internal.py:wandb_internal():148] Internal process interrupted.
2023-03-20 16:11:47,071 INFO    WriterThread:5613 [datastore.py:close():281] close: /home/utente/Scrivania/PROVA/LADD/wandb/run-20230320_161119-qq2aefz1/run-qq2aefz1.wandb
2023-03-20 16:11:47,093 INFO    HandlerThread:5613 [handler.py:finish():683] shutting down handler
2023-03-20 16:11:57,979 INFO    SenderThread:5613 [dir_watcher.py:__init__():169] watching files in: /home/utente/Scrivania/PROVA/LADD/wandb/run-20230320_161119-qq2aefz1/files
2023-03-20 16:11:57,979 INFO    SenderThread:5613 [sender.py:_start_run_threads():740] run started: qq2aefz1 with start time 1679325079
2023-03-20 16:11:57,979 INFO    SenderThread:5613 [sender.py:finish():979] shutting down sender
2023-03-20 16:11:57,979 INFO    SenderThread:5613 [dir_watcher.py:finish():283] shutting down directory watcher
2023-03-20 16:11:58,980 INFO    SenderThread:5613 [dir_watcher.py:finish():313] scan: /home/utente/Scrivania/PROVA/LADD/wandb/run-20230320_161119-qq2aefz1/files
2023-03-20 16:11:58,980 INFO    SenderThread:5613 [dir_watcher.py:finish():327] scan save: /home/utente/Scrivania/PROVA/LADD/wandb/run-20230320_161119-qq2aefz1/files/config.yaml config.yaml
2023-03-20 16:11:58,981 INFO    SenderThread:5613 [file_pusher.py:finish():177] shutting down file pusher
2023-03-20 16:11:58,981 INFO    SenderThread:5613 [file_pusher.py:join():182] waiting for file pusher
2023-03-20 16:11:59,860 INFO    Thread-10 :5613 [upload_job.py:push():137] Uploaded file /home/utente/Scrivania/PROVA/LADD/wandb/run-20230320_161119-qq2aefz1/files/config.yaml
2023-03-20 16:12:00,784 INFO    MainThread:5613 [internal.py:handle_exit():76] Internal process exited
