2023-06-10 19:39:35,464 INFO    MainThread:8016 [internal.py:wandb_internal():86] W&B internal server running at pid: 8016, started at: 2023-06-10 19:39:35.463685
2023-06-10 19:39:35,468 DEBUG   HandlerThread:8016 [handler.py:handle_request():126] handle_request: check_version
2023-06-10 19:39:35,468 INFO    WriterThread:8016 [datastore.py:open_for_write():77] open: /home/utente/Scrivania/PROVA/LADD/wandb/run-20230610_193934-2of5vwjd/run-2of5vwjd.wandb
2023-06-10 19:39:35,471 DEBUG   SenderThread:8016 [sender.py:send():182] send: header
2023-06-10 19:39:35,471 DEBUG   SenderThread:8016 [sender.py:send_request():196] send_request: check_version
2023-06-10 19:39:36,235 DEBUG   SenderThread:8016 [sender.py:send():182] send: run
2023-06-10 19:39:36,238 INFO    SenderThread:8016 [sender.py:_maybe_setup_resume():421] checking resume status for alessandro-fella-1/federated_cityscapes/2of5vwjd
2023-06-10 19:39:37,500 INFO    SenderThread:8016 [dir_watcher.py:__init__():169] watching files in: /home/utente/Scrivania/PROVA/LADD/wandb/run-20230610_193934-2of5vwjd/files
2023-06-10 19:39:37,500 INFO    SenderThread:8016 [sender.py:_start_run_threads():740] run started: 2of5vwjd with start time 1686418774
2023-06-10 19:39:37,500 DEBUG   SenderThread:8016 [sender.py:send():182] send: summary
2023-06-10 19:39:37,500 INFO    SenderThread:8016 [sender.py:_save_file():873] saving file wandb-summary.json with policy end
2023-06-10 19:39:37,501 DEBUG   HandlerThread:8016 [handler.py:handle_request():126] handle_request: run_start
2023-06-10 19:39:37,505 DEBUG   HandlerThread:8016 [meta.py:__init__():40] meta init
2023-06-10 19:39:37,506 DEBUG   HandlerThread:8016 [meta.py:__init__():54] meta init done
2023-06-10 19:39:37,506 DEBUG   HandlerThread:8016 [meta.py:probe():211] probe
2023-06-10 19:39:37,513 DEBUG   HandlerThread:8016 [meta.py:_setup_git():201] setup git
2023-06-10 19:39:37,530 DEBUG   HandlerThread:8016 [meta.py:_setup_git():208] setup git done
2023-06-10 19:39:37,530 DEBUG   HandlerThread:8016 [meta.py:_save_pip():58] save pip
2023-06-10 19:39:37,532 DEBUG   HandlerThread:8016 [meta.py:_save_pip():72] save pip done
2023-06-10 19:39:37,532 DEBUG   HandlerThread:8016 [meta.py:_save_conda():79] save conda
2023-06-10 19:39:38,504 INFO    Thread-13 :8016 [dir_watcher.py:_on_file_created():217] file/dir created: /home/utente/Scrivania/PROVA/LADD/wandb/run-20230610_193934-2of5vwjd/files/wandb-summary.json
2023-06-10 19:39:38,505 INFO    Thread-13 :8016 [dir_watcher.py:_on_file_created():217] file/dir created: /home/utente/Scrivania/PROVA/LADD/wandb/run-20230610_193934-2of5vwjd/files/requirements.txt
2023-06-10 19:39:38,505 INFO    Thread-13 :8016 [dir_watcher.py:_on_file_created():217] file/dir created: /home/utente/Scrivania/PROVA/LADD/wandb/run-20230610_193934-2of5vwjd/files/conda-environment.yaml
2023-06-10 19:39:39,444 DEBUG   HandlerThread:8016 [meta.py:_save_conda():87] save conda done
2023-06-10 19:39:39,444 DEBUG   HandlerThread:8016 [meta.py:probe():249] probe done
2023-06-10 19:39:39,514 INFO    Thread-13 :8016 [dir_watcher.py:_on_file_modified():230] file/dir modified: /home/utente/Scrivania/PROVA/LADD/wandb/run-20230610_193934-2of5vwjd/files/conda-environment.yaml
2023-06-10 19:39:39,515 INFO    Thread-13 :8016 [dir_watcher.py:_on_file_created():217] file/dir created: /home/utente/Scrivania/PROVA/LADD/wandb/run-20230610_193934-2of5vwjd/files/wandb-metadata.json
2023-06-10 19:39:39,553 DEBUG   SenderThread:8016 [sender.py:send():182] send: files
2023-06-10 19:39:39,553 INFO    SenderThread:8016 [sender.py:_save_file():873] saving file wandb-metadata.json with policy now
2023-06-10 19:39:39,564 DEBUG   HandlerThread:8016 [handler.py:handle_request():126] handle_request: stop_status
2023-06-10 19:39:39,564 DEBUG   SenderThread:8016 [sender.py:send_request():196] send_request: stop_status
2023-06-10 19:39:39,808 DEBUG   SenderThread:8016 [sender.py:send():182] send: metric
2023-06-10 19:39:39,809 DEBUG   SenderThread:8016 [sender.py:send():182] send: metric
2023-06-10 19:39:39,809 WARNING SenderThread:8016 [sender.py:send_metric():831] Seen metric with glob (shouldnt happen)
2023-06-10 19:39:39,809 DEBUG   SenderThread:8016 [sender.py:send():182] send: config
2023-06-10 19:39:40,238 INFO    Thread-16 :8016 [upload_job.py:push():137] Uploaded file /tmp/tmpts9tldl8wandb/15wjk41b-wandb-metadata.json
2023-06-10 19:39:40,515 INFO    Thread-13 :8016 [dir_watcher.py:_on_file_created():217] file/dir created: /home/utente/Scrivania/PROVA/LADD/wandb/run-20230610_193934-2of5vwjd/files/output.log
2023-06-10 19:39:44,518 INFO    Thread-13 :8016 [dir_watcher.py:_on_file_modified():230] file/dir modified: /home/utente/Scrivania/PROVA/LADD/wandb/run-20230610_193934-2of5vwjd/files/output.log
2023-06-10 19:39:54,885 DEBUG   HandlerThread:8016 [handler.py:handle_request():126] handle_request: stop_status
2023-06-10 19:39:54,886 DEBUG   SenderThread:8016 [sender.py:send_request():196] send_request: stop_status
2023-06-10 19:40:05,891 DEBUG   SenderThread:8016 [sender.py:send():182] send: stats
2023-06-10 19:40:06,543 INFO    Thread-13 :8016 [dir_watcher.py:_on_file_modified():230] file/dir modified: /home/utente/Scrivania/PROVA/LADD/wandb/run-20230610_193934-2of5vwjd/files/config.yaml
2023-06-10 19:40:10,115 DEBUG   HandlerThread:8016 [handler.py:handle_request():126] handle_request: stop_status
2023-06-10 19:40:10,116 DEBUG   SenderThread:8016 [sender.py:send_request():196] send_request: stop_status
2023-06-10 19:40:25,600 DEBUG   HandlerThread:8016 [handler.py:handle_request():126] handle_request: stop_status
2023-06-10 19:40:25,601 DEBUG   SenderThread:8016 [sender.py:send_request():196] send_request: stop_status
2023-06-10 19:40:36,271 DEBUG   SenderThread:8016 [sender.py:send():182] send: stats
2023-06-10 19:40:40,916 DEBUG   HandlerThread:8016 [handler.py:handle_request():126] handle_request: stop_status
2023-06-10 19:40:40,917 DEBUG   SenderThread:8016 [sender.py:send_request():196] send_request: stop_status
2023-06-10 19:40:56,175 DEBUG   HandlerThread:8016 [handler.py:handle_request():126] handle_request: stop_status
2023-06-10 19:40:56,176 DEBUG   SenderThread:8016 [sender.py:send_request():196] send_request: stop_status
2023-06-10 19:41:06,600 DEBUG   SenderThread:8016 [sender.py:send():182] send: stats
2023-06-10 19:41:11,433 DEBUG   HandlerThread:8016 [handler.py:handle_request():126] handle_request: stop_status
2023-06-10 19:41:11,433 DEBUG   SenderThread:8016 [sender.py:send_request():196] send_request: stop_status
2023-06-10 19:41:26,794 DEBUG   HandlerThread:8016 [handler.py:handle_request():126] handle_request: stop_status
2023-06-10 19:41:26,795 DEBUG   SenderThread:8016 [sender.py:send_request():196] send_request: stop_status
2023-06-10 19:41:36,969 DEBUG   SenderThread:8016 [sender.py:send():182] send: stats
2023-06-10 19:41:42,327 DEBUG   HandlerThread:8016 [handler.py:handle_request():126] handle_request: stop_status
2023-06-10 19:41:42,328 DEBUG   SenderThread:8016 [sender.py:send_request():196] send_request: stop_status
2023-06-10 19:41:57,618 DEBUG   HandlerThread:8016 [handler.py:handle_request():126] handle_request: stop_status
2023-06-10 19:41:57,619 DEBUG   SenderThread:8016 [sender.py:send_request():196] send_request: stop_status
2023-06-10 19:42:07,368 DEBUG   SenderThread:8016 [sender.py:send():182] send: stats
2023-06-10 19:42:12,870 DEBUG   HandlerThread:8016 [handler.py:handle_request():126] handle_request: stop_status
2023-06-10 19:42:12,871 DEBUG   SenderThread:8016 [sender.py:send_request():196] send_request: stop_status
2023-06-10 19:42:33,152 DEBUG   HandlerThread:8016 [handler.py:handle_request():126] handle_request: stop_status
2023-06-10 19:42:33,153 DEBUG   SenderThread:8016 [sender.py:send_request():196] send_request: stop_status
2023-06-10 19:42:38,697 DEBUG   SenderThread:8016 [sender.py:send():182] send: stats
2023-06-10 19:42:53,701 DEBUG   HandlerThread:8016 [handler.py:handle_request():126] handle_request: stop_status
2023-06-10 19:42:53,702 DEBUG   SenderThread:8016 [sender.py:send_request():196] send_request: stop_status
2023-06-10 19:43:08,167 DEBUG   SenderThread:8016 [sender.py:send():182] send: stats
2023-06-10 19:43:08,937 DEBUG   HandlerThread:8016 [handler.py:handle_request():126] handle_request: stop_status
2023-06-10 19:43:08,939 DEBUG   SenderThread:8016 [sender.py:send_request():196] send_request: stop_status
2023-06-10 19:43:24,187 DEBUG   HandlerThread:8016 [handler.py:handle_request():126] handle_request: stop_status
2023-06-10 19:43:24,188 DEBUG   SenderThread:8016 [sender.py:send_request():196] send_request: stop_status
2023-06-10 19:43:38,504 DEBUG   SenderThread:8016 [sender.py:send():182] send: stats
2023-06-10 19:43:39,461 DEBUG   HandlerThread:8016 [handler.py:handle_request():126] handle_request: stop_status
2023-06-10 19:43:39,461 DEBUG   SenderThread:8016 [sender.py:send_request():196] send_request: stop_status
2023-06-10 19:43:55,279 DEBUG   HandlerThread:8016 [handler.py:handle_request():126] handle_request: stop_status
2023-06-10 19:43:55,280 DEBUG   SenderThread:8016 [sender.py:send_request():196] send_request: stop_status
2023-06-10 19:44:08,890 DEBUG   SenderThread:8016 [sender.py:send():182] send: stats
2023-06-10 19:44:10,713 DEBUG   HandlerThread:8016 [handler.py:handle_request():126] handle_request: stop_status
2023-06-10 19:44:10,714 DEBUG   SenderThread:8016 [sender.py:send_request():196] send_request: stop_status
2023-06-10 19:44:26,612 DEBUG   HandlerThread:8016 [handler.py:handle_request():126] handle_request: stop_status
2023-06-10 19:44:26,612 DEBUG   SenderThread:8016 [sender.py:send_request():196] send_request: stop_status
2023-06-10 19:44:39,297 DEBUG   SenderThread:8016 [sender.py:send():182] send: stats
2023-06-10 19:44:42,290 DEBUG   HandlerThread:8016 [handler.py:handle_request():126] handle_request: stop_status
2023-06-10 19:44:42,291 DEBUG   SenderThread:8016 [sender.py:send_request():196] send_request: stop_status
2023-06-10 19:45:45,866 ERROR   SenderThread:8016 [retry.py:__call__():126] Retry attempt failed:
Traceback (most recent call last):
  File "/home/utente/anaconda3/envs/LADD/lib/python3.9/site-packages/urllib3/connection.py", line 174, in _new_conn
    conn = connection.create_connection(
  File "/home/utente/anaconda3/envs/LADD/lib/python3.9/site-packages/urllib3/util/connection.py", line 73, in create_connection
    for res in socket.getaddrinfo(host, port, family, socket.SOCK_STREAM):
  File "/home/utente/anaconda3/envs/LADD/lib/python3.9/socket.py", line 954, in getaddrinfo
    for res in _socket.getaddrinfo(host, port, family, type, proto, flags):
socket.gaierror: [Errno -3] Temporary failure in name resolution

During handling of the above exception, another exception occurred:

Traceback (most recent call last):
  File "/home/utente/anaconda3/envs/LADD/lib/python3.9/site-packages/urllib3/connectionpool.py", line 699, in urlopen
    httplib_response = self._make_request(
  File "/home/utente/anaconda3/envs/LADD/lib/python3.9/site-packages/urllib3/connectionpool.py", line 382, in _make_request
    self._validate_conn(conn)
  File "/home/utente/anaconda3/envs/LADD/lib/python3.9/site-packages/urllib3/connectionpool.py", line 1010, in _validate_conn
    conn.connect()
  File "/home/utente/anaconda3/envs/LADD/lib/python3.9/site-packages/urllib3/connection.py", line 358, in connect
    conn = self._new_conn()
  File "/home/utente/anaconda3/envs/LADD/lib/python3.9/site-packages/urllib3/connection.py", line 186, in _new_conn
    raise NewConnectionError(
urllib3.exceptions.NewConnectionError: <urllib3.connection.HTTPSConnection object at 0x7f56b10bb460>: Failed to establish a new connection: [Errno -3] Temporary failure in name resolution

During handling of the above exception, another exception occurred:

Traceback (most recent call last):
  File "/home/utente/anaconda3/envs/LADD/lib/python3.9/site-packages/requests/adapters.py", line 440, in send
    resp = conn.urlopen(
  File "/home/utente/anaconda3/envs/LADD/lib/python3.9/site-packages/urllib3/connectionpool.py", line 755, in urlopen
    retries = retries.increment(
  File "/home/utente/anaconda3/envs/LADD/lib/python3.9/site-packages/urllib3/util/retry.py", line 574, in increment
    raise MaxRetryError(_pool, url, error or ResponseError(cause))
urllib3.exceptions.MaxRetryError: HTTPSConnectionPool(host='api.wandb.ai', port=443): Max retries exceeded with url: /graphql (Caused by NewConnectionError('<urllib3.connection.HTTPSConnection object at 0x7f56b10bb460>: Failed to establish a new connection: [Errno -3] Temporary failure in name resolution'))

During handling of the above exception, another exception occurred:

Traceback (most recent call last):
  File "/home/utente/anaconda3/envs/LADD/lib/python3.9/site-packages/wandb/sdk/lib/retry.py", line 102, in __call__
    result = self._call_fn(*args, **kwargs)
  File "/home/utente/anaconda3/envs/LADD/lib/python3.9/site-packages/wandb/sdk/internal/internal_api.py", line 130, in execute
    return self.client.execute(*args, **kwargs)
  File "/home/utente/anaconda3/envs/LADD/lib/python3.9/site-packages/wandb/vendor/gql-0.2.0/gql/client.py", line 52, in execute
    result = self._get_result(document, *args, **kwargs)
  File "/home/utente/anaconda3/envs/LADD/lib/python3.9/site-packages/wandb/vendor/gql-0.2.0/gql/client.py", line 60, in _get_result
    return self.transport.execute(document, *args, **kwargs)
  File "/home/utente/anaconda3/envs/LADD/lib/python3.9/site-packages/wandb/vendor/gql-0.2.0/gql/transport/requests.py", line 38, in execute
    request = requests.post(self.url, **post_args)
  File "/home/utente/anaconda3/envs/LADD/lib/python3.9/site-packages/requests/api.py", line 117, in post
    return request('post', url, data=data, json=json, **kwargs)
  File "/home/utente/anaconda3/envs/LADD/lib/python3.9/site-packages/requests/api.py", line 61, in request
    return session.request(method=method, url=url, **kwargs)
  File "/home/utente/anaconda3/envs/LADD/lib/python3.9/site-packages/requests/sessions.py", line 529, in request
    resp = self.send(prep, **send_kwargs)
  File "/home/utente/anaconda3/envs/LADD/lib/python3.9/site-packages/requests/sessions.py", line 645, in send
    r = adapter.send(request, **kwargs)
  File "/home/utente/anaconda3/envs/LADD/lib/python3.9/site-packages/requests/adapters.py", line 519, in send
    raise ConnectionError(e, request=request)
requests.exceptions.ConnectionError: HTTPSConnectionPool(host='api.wandb.ai', port=443): Max retries exceeded with url: /graphql (Caused by NewConnectionError('<urllib3.connection.HTTPSConnection object at 0x7f56b10bb460>: Failed to establish a new connection: [Errno -3] Temporary failure in name resolution'))
2023-06-10 19:47:56,413 WARNING MainThread:8016 [internal.py:wandb_internal():145] Internal process interrupt: 1
2023-06-10 19:47:58,636 DEBUG   HandlerThread:8016 [handler.py:handle_request():126] handle_request: poll_exit
2023-06-10 19:47:59,029 INFO    Thread-13 :8016 [dir_watcher.py:_on_file_modified():230] file/dir modified: /home/utente/Scrivania/PROVA/LADD/wandb/run-20230610_193934-2of5vwjd/files/output.log
2023-06-10 19:48:03,736 DEBUG   HandlerThread:8016 [handler.py:handle_request():126] handle_request: poll_exit
2023-06-10 19:48:08,836 DEBUG   HandlerThread:8016 [handler.py:handle_request():126] handle_request: poll_exit
2023-06-10 19:48:13,938 DEBUG   HandlerThread:8016 [handler.py:handle_request():126] handle_request: poll_exit
2023-06-10 19:48:19,039 DEBUG   HandlerThread:8016 [handler.py:handle_request():126] handle_request: poll_exit
