2023-03-16 18:17:25,061 INFO    MainThread:13754 [internal.py:wandb_internal():86] W&B internal server running at pid: 13754, started at: 2023-03-16 18:17:25.060676
2023-03-16 18:17:25,066 INFO    WriterThread:13754 [datastore.py:open_for_write():77] open: /home/utente/Scrivania/PROVA/LADD/wandb/run-20230316_181723-3hrx6qa7/run-3hrx6qa7.wandb
2023-03-16 18:17:25,066 DEBUG   HandlerThread:13754 [handler.py:handle_request():126] handle_request: check_version
2023-03-16 18:17:25,069 DEBUG   SenderThread:13754 [sender.py:send():182] send: header
2023-03-16 18:17:25,069 DEBUG   SenderThread:13754 [sender.py:send_request():196] send_request: check_version
2023-03-16 18:17:25,086 DEBUG   SenderThread:13754 [sender.py:send():182] send: run
2023-03-16 18:17:25,089 INFO    SenderThread:13754 [sender.py:_maybe_setup_resume():421] checking resume status for alessandro-fella-1/federated_cityscapes/3hrx6qa7
2023-03-16 18:17:28,724 ERROR   SenderThread:13754 [retry.py:__call__():126] Retry attempt failed:
Traceback (most recent call last):
  File "/home/utente/anaconda3/envs/LADD/lib/python3.9/site-packages/urllib3/connection.py", line 174, in _new_conn
    conn = connection.create_connection(
  File "/home/utente/anaconda3/envs/LADD/lib/python3.9/site-packages/urllib3/util/connection.py", line 73, in create_connection
    for res in socket.getaddrinfo(host, port, family, socket.SOCK_STREAM):
  File "/home/utente/anaconda3/envs/LADD/lib/python3.9/socket.py", line 954, in getaddrinfo
    for res in _socket.getaddrinfo(host, port, family, type, proto, flags):
socket.gaierror: [Errno -3] Temporary failure in name resolution

During handling of the above exception, another exception occurred:

Traceback (most recent call last):
  File "/home/utente/anaconda3/envs/LADD/lib/python3.9/site-packages/urllib3/connectionpool.py", line 699, in urlopen
    httplib_response = self._make_request(
  File "/home/utente/anaconda3/envs/LADD/lib/python3.9/site-packages/urllib3/connectionpool.py", line 382, in _make_request
    self._validate_conn(conn)
  File "/home/utente/anaconda3/envs/LADD/lib/python3.9/site-packages/urllib3/connectionpool.py", line 1010, in _validate_conn
    conn.connect()
  File "/home/utente/anaconda3/envs/LADD/lib/python3.9/site-packages/urllib3/connection.py", line 358, in connect
    conn = self._new_conn()
  File "/home/utente/anaconda3/envs/LADD/lib/python3.9/site-packages/urllib3/connection.py", line 186, in _new_conn
    raise NewConnectionError(
urllib3.exceptions.NewConnectionError: <urllib3.connection.HTTPSConnection object at 0x7f9af84cba90>: Failed to establish a new connection: [Errno -3] Temporary failure in name resolution

During handling of the above exception, another exception occurred:

Traceback (most recent call last):
  File "/home/utente/anaconda3/envs/LADD/lib/python3.9/site-packages/requests/adapters.py", line 440, in send
    resp = conn.urlopen(
  File "/home/utente/anaconda3/envs/LADD/lib/python3.9/site-packages/urllib3/connectionpool.py", line 755, in urlopen
    retries = retries.increment(
  File "/home/utente/anaconda3/envs/LADD/lib/python3.9/site-packages/urllib3/util/retry.py", line 574, in increment
    raise MaxRetryError(_pool, url, error or ResponseError(cause))
urllib3.exceptions.MaxRetryError: HTTPSConnectionPool(host='api.wandb.ai', port=443): Max retries exceeded with url: /graphql (Caused by NewConnectionError('<urllib3.connection.HTTPSConnection object at 0x7f9af84cba90>: Failed to establish a new connection: [Errno -3] Temporary failure in name resolution'))

During handling of the above exception, another exception occurred:

Traceback (most recent call last):
  File "/home/utente/anaconda3/envs/LADD/lib/python3.9/site-packages/wandb/sdk/lib/retry.py", line 102, in __call__
    result = self._call_fn(*args, **kwargs)
  File "/home/utente/anaconda3/envs/LADD/lib/python3.9/site-packages/wandb/sdk/internal/internal_api.py", line 130, in execute
    return self.client.execute(*args, **kwargs)
  File "/home/utente/anaconda3/envs/LADD/lib/python3.9/site-packages/wandb/vendor/gql-0.2.0/gql/client.py", line 52, in execute
    result = self._get_result(document, *args, **kwargs)
  File "/home/utente/anaconda3/envs/LADD/lib/python3.9/site-packages/wandb/vendor/gql-0.2.0/gql/client.py", line 60, in _get_result
    return self.transport.execute(document, *args, **kwargs)
  File "/home/utente/anaconda3/envs/LADD/lib/python3.9/site-packages/wandb/vendor/gql-0.2.0/gql/transport/requests.py", line 38, in execute
    request = requests.post(self.url, **post_args)
  File "/home/utente/anaconda3/envs/LADD/lib/python3.9/site-packages/requests/api.py", line 117, in post
    return request('post', url, data=data, json=json, **kwargs)
  File "/home/utente/anaconda3/envs/LADD/lib/python3.9/site-packages/requests/api.py", line 61, in request
    return session.request(method=method, url=url, **kwargs)
  File "/home/utente/anaconda3/envs/LADD/lib/python3.9/site-packages/requests/sessions.py", line 529, in request
    resp = self.send(prep, **send_kwargs)
  File "/home/utente/anaconda3/envs/LADD/lib/python3.9/site-packages/requests/sessions.py", line 645, in send
    r = adapter.send(request, **kwargs)
  File "/home/utente/anaconda3/envs/LADD/lib/python3.9/site-packages/requests/adapters.py", line 519, in send
    raise ConnectionError(e, request=request)
requests.exceptions.ConnectionError: HTTPSConnectionPool(host='api.wandb.ai', port=443): Max retries exceeded with url: /graphql (Caused by NewConnectionError('<urllib3.connection.HTTPSConnection object at 0x7f9af84cba90>: Failed to establish a new connection: [Errno -3] Temporary failure in name resolution'))
2023-03-16 18:17:29,359 WARNING MainThread:13754 [internal.py:wandb_internal():145] Internal process interrupt: 1
